Traceback (most recent call last):
  File "/usr/lib/python3/dist-packages/urllib3/response.py", line 425, in _error_catcher
    yield
  File "/usr/lib/python3/dist-packages/urllib3/response.py", line 752, in read_chunked
    self._update_chunk_length()
  File "/usr/lib/python3/dist-packages/urllib3/response.py", line 682, in _update_chunk_length
    line = self._fp.fp.readline()
  File "/usr/lib/python3.8/socket.py", line 669, in readinto
    return self._sock.recv_into(b)
  File "/usr/lib/python3.8/ssl.py", line 1241, in recv_into
    return self.read(nbytes, buffer)
  File "/usr/lib/python3.8/ssl.py", line 1099, in read
    return self._sslobj.read(len, buffer)
socket.timeout: The read operation timed out

During handling of the above exception, another exception occurred:

Traceback (most recent call last):
  File "/home/zhenyean/.local/lib/python3.8/site-packages/requests/models.py", line 753, in generate
    for chunk in self.raw.stream(chunk_size, decode_content=True):
  File "/usr/lib/python3/dist-packages/urllib3/response.py", line 560, in stream
    for line in self.read_chunked(amt, decode_content=decode_content):
  File "/usr/lib/python3/dist-packages/urllib3/response.py", line 781, in read_chunked
    self._original_response.close()
  File "/usr/lib/python3.8/contextlib.py", line 131, in __exit__
    self.gen.throw(type, value, traceback)
  File "/usr/lib/python3/dist-packages/urllib3/response.py", line 430, in _error_catcher
    raise ReadTimeoutError(self._pool, None, "Read timed out.")
urllib3.exceptions.ReadTimeoutError: HTTPSConnectionPool(host='fapi.binance.com', port=443): Read timed out.

During handling of the above exception, another exception occurred:

Traceback (most recent call last):
  File "run.py", line 164, in <module>
    trade_action(get_position_info(), get_current_trend(), get_minute_candle())
  File "run.py", line 135, in get_position_info
    positionAmt = float(client.futures_position_information(symbol=symbol, timestamp=get_timestamp())[0].get('positionAmt'))
  File "/home/zhenyean/.local/lib/python3.8/site-packages/binance/client.py", line 3688, in futures_position_information
    return self._request_futures_api('get', 'positionRisk', True, data=params)
  File "/home/zhenyean/.local/lib/python3.8/site-packages/binance/client.py", line 222, in _request_futures_api
    return self._request(method, uri, signed, True, **kwargs)
  File "/home/zhenyean/.local/lib/python3.8/site-packages/binance/client.py", line 196, in _request
    self.response = getattr(self.session, method)(uri, **kwargs)
  File "/home/zhenyean/.local/lib/python3.8/site-packages/requests/sessions.py", line 555, in get
    return self.request('GET', url, **kwargs)
  File "/home/zhenyean/.local/lib/python3.8/site-packages/requests/sessions.py", line 542, in request
    resp = self.send(prep, **send_kwargs)
  File "/home/zhenyean/.local/lib/python3.8/site-packages/requests/sessions.py", line 697, in send
    r.content
  File "/home/zhenyean/.local/lib/python3.8/site-packages/requests/models.py", line 831, in content
    self._content = b''.join(self.iter_content(CONTENT_CHUNK_SIZE)) or b''
  File "/home/zhenyean/.local/lib/python3.8/site-packages/requests/models.py", line 760, in generate
    raise ConnectionError(e)
requests.exceptions.ConnectionError: HTTPSConnectionPool(host='fapi.binance.com', port=443): Read timed out.